<?xml version="1.0"?>
<robot xmlns:xacro="http://www.ros.org/wiki/xacro">

    <material name="white">
        <color rgba="1 1 1 1"/>
    </material>

    <material name="orange">
        <color rgba="1 0.3 0.1 1"/>
    </material>

    <material name="blue">
        <color rgba="0.2 0.2 1 1"/>
    </material>

    <material name="black">
        <color rgba="0 0 0 1"/>
    </material>
	
	<material name="red">
		<color rgba="1 0 0 1"/>
	</material>

    <link name="base_link">
    </link>

    <joint name="chassis_joint" type="fixed">
        <parent link="base_link"/>
        <child link="chassis"/>
        <origin xyz="-0.1 0 0"/>
    </joint>

    <!-- CHASSIS -->
    <link name="chassis">
        <visual>
            <origin xyz="0.10 0 0.035" rpy="0 0 0"/>
            <geometry>
                <box size="0.20 0.19 0.13"/>
            </geometry>
            <material name="white"/>
        </visual>
        <collision>
            <origin xyz="0.10 0 0.035" rpy="0 0 0"/>
            <geometry>
                <box size="0.20 0.19 0.13"/>
            </geometry>
        </collision>
        <!-- ... intertia ... -->
        <xacro:inertial_box mass="0.5" x="0.20" y="0.19" z="0.13">
            <origin xyz="0.15 0 0.075" rpy="0 0 0"/>
        </xacro:inertial_box>
    </link>
	<gazebo reference="chassis">
		<material>Gazebo/White</material>
	</gazebo>	
    
	<!-- LEFT BACK WHEEL -->
    <joint name="left_back_wheel_joint" type="continuous">
        <parent link="base_link"/>
        <child link="left_back_wheel"/>
        <origin xyz="-0.0675 0.08 0" rpy="-${pi/2} 0 0" />
        <axis xyz="0 0 1"/>
    </joint>

    <link name="left_back_wheel">
        <visual>
            <geometry>
                <cylinder radius="0.035" length="0.06"/>
            </geometry>
            <material name="blue"/>
        </visual>
        <collision>
            <geometry>
                <!-- <cylinder radius="0.035" length="0.06"/> -->
                <sphere  radius="0.035"/>
            </geometry>
        </collision>
        <!-- ... intertia ... -->
        <xacro:inertial_cylinder mass="0.1" length="0.035" radius="0.06">
            <origin xyz="0 0 0" rpy="0 0 0"/>
        </xacro:inertial_cylinder>
    </link>
	
	<gazebo reference="left_back_wheel">
		<material>Gazebo/Blue</material>
	</gazebo>

    <!-- LEFT FRONT WHEEL -->
    <joint name="left_front_wheel_joint" type="continuous"> <!--   continuous -->
        <parent link="base_link"/> <!--   base_link -->
        <child link="left_front_wheel"/>
        <origin xyz="0.0675 0.08 0" rpy="-${pi/2} 0 0"/>
        <axis xyz="0 0 1"/>
    </joint>

    <link name="left_front_wheel">
        <visual>
            <geometry>
                <cylinder radius="0.035" length="0.06" />
            </geometry>
            <material name="blue"/>
        </visual>
        <collision>
            <geometry>
                <cylinder radius="0.035" length="0.06"/>
            </geometry>
        </collision>
		<!-- ... intertia ... -->
        <xacro:inertial_cylinder mass="0.1" length="0.035" radius="0.06">
            <origin xyz="0 0 0" rpy="0 0 0"/>
        </xacro:inertial_cylinder>
    </link>
	
	<gazebo reference="left_front_wheel">
		<material>Gazebo/Blue</material>
		<mu1 value="0.1"/>
		<mu2 value="0.1"/>
	</gazebo>

    <!-- RIGHT BACK WHEEL -->
    <joint name="right_back_wheel_joint" type="continuous">
        <parent link="base_link"/>
        <child link="right_back_wheel"/>
        <origin xyz="-0.0675 -0.08 0" rpy="${pi/2} 0 0"/>
        <axis xyz="0 0 -1"/>
    </joint>

    <link name="right_back_wheel">
        <visual>
            <geometry>
                <cylinder radius="0.035" length="0.06" />
            </geometry>
            <material name="blue"/>
        </visual>
        <collision>
            <geometry>
                <!-- <cylinder radius="0.035" length="0.06"/> -->
                <sphere  radius="0.035"/>
			</geometry>
        </collision>
        <!-- ... intertia ... -->
        <xacro:inertial_cylinder mass="0.1" length="0.035" radius="0.06">
            <origin xyz="0 0 0" rpy="0 0 0"/>
        </xacro:inertial_cylinder>
    </link>
	
	<gazebo reference="right_back_wheel">
		<material>Gazebo/Blue</material>
	</gazebo>

    <!-- RIGHT FRONT WHEEL -->
    <joint name="right_front_wheel_joint" type="continuous">  <!--   continuous -->
        <parent link="base_link"/>  <!--   base_link -->
        <child link="right_front_wheel"/>
        <origin xyz="0.0675 -0.08 0" rpy="${pi/2} 0 0"/>
        <axis xyz="0 0 -1"/>
    </joint>

    <link name="right_front_wheel">
        <visual>
            <geometry>
                <cylinder radius="0.035" length="0.06" />
            </geometry>
            <material name="blue"/>
        </visual>
        <collision>
            <geometry>
                <cylinder radius="0.035" length="0.06"/>
            </geometry>
        </collision>
        <!-- ... intertia ... -->
        <xacro:inertial_cylinder mass="0.1" length="0.035" radius="0.06">
            <origin xyz="0 0 0" rpy="0 0 0"/>
        </xacro:inertial_cylinder>
    </link>

	<gazebo reference="right_front_wheel">
		<material>Gazebo/Blue</material>
		<mu1 value="0.1"/>
		<mu2 value="0.1"/>
	</gazebo>

</robot>
